[2022-12-29T21:11:07.285+0000] {taskinstance.py:1087} INFO - Dependencies all met for <TaskInstance: a_initial_load.create_database manual__2022-12-29T21:11:06.288494+00:00 [queued]>
[2022-12-29T21:11:07.295+0000] {taskinstance.py:1087} INFO - Dependencies all met for <TaskInstance: a_initial_load.create_database manual__2022-12-29T21:11:06.288494+00:00 [queued]>
[2022-12-29T21:11:07.295+0000] {taskinstance.py:1283} INFO - 
--------------------------------------------------------------------------------
[2022-12-29T21:11:07.295+0000] {taskinstance.py:1284} INFO - Starting attempt 1 of 1
[2022-12-29T21:11:07.295+0000] {taskinstance.py:1285} INFO - 
--------------------------------------------------------------------------------
[2022-12-29T21:11:07.306+0000] {taskinstance.py:1304} INFO - Executing <Task(PythonOperator): create_database> on 2022-12-29 21:11:06.288494+00:00
[2022-12-29T21:11:07.314+0000] {standard_task_runner.py:55} INFO - Started process 2130 to run task
[2022-12-29T21:11:07.317+0000] {standard_task_runner.py:82} INFO - Running: ['***', 'tasks', 'run', 'a_initial_load', 'create_database', 'manual__2022-12-29T21:11:06.288494+00:00', '--job-id', '25', '--raw', '--subdir', 'DAGS_FOLDER/initial_load.py', '--cfg-path', '/tmp/tmpt5piqvj3']
[2022-12-29T21:11:07.319+0000] {standard_task_runner.py:83} INFO - Job 25: Subtask create_database
[2022-12-29T21:11:07.367+0000] {task_command.py:389} INFO - Running <TaskInstance: a_initial_load.create_database manual__2022-12-29T21:11:06.288494+00:00 [running]> on host 617cc505ea19
[2022-12-29T21:11:07.429+0000] {taskinstance.py:1513} INFO - Exporting the following env vars:
AIRFLOW_CTX_DAG_OWNER=***
AIRFLOW_CTX_DAG_ID=a_initial_load
AIRFLOW_CTX_TASK_ID=create_database
AIRFLOW_CTX_EXECUTION_DATE=2022-12-29T21:11:06.288494+00:00
AIRFLOW_CTX_TRY_NUMBER=1
AIRFLOW_CTX_DAG_RUN_ID=manual__2022-12-29T21:11:06.288494+00:00
[2022-12-29T21:11:07.437+0000] {logging_mixin.py:137} INFO - CREATE DATABASE stocks
[2022-12-29T21:11:07.437+0000] {taskinstance.py:1772} ERROR - Task failed with exception
Traceback (most recent call last):
  File "/home/airflow/.local/lib/python3.7/site-packages/airflow/operators/python.py", line 175, in execute
    return_value = self.execute_callable()
  File "/home/airflow/.local/lib/python3.7/site-packages/airflow/operators/python.py", line 192, in execute_callable
    return self.python_callable(*self.op_args, **self.op_kwargs)
  File "/opt/airflow/dags/initial_load.py", line 199, in create_database
    cursor.execute(sql)
psycopg2.errors.DuplicateDatabase: database "stocks" already exists

[2022-12-29T21:11:07.446+0000] {taskinstance.py:1327} INFO - Marking task as FAILED. dag_id=a_initial_load, task_id=create_database, execution_date=20221229T211106, start_date=20221229T211107, end_date=20221229T211107
[2022-12-29T21:11:07.456+0000] {standard_task_runner.py:105} ERROR - Failed to execute job 25 for task create_database (database "stocks" already exists
; 2130)
[2022-12-29T21:11:07.487+0000] {local_task_job.py:159} INFO - Task exited with return code 1
[2022-12-29T21:11:07.514+0000] {taskinstance.py:2582} INFO - 0 downstream tasks scheduled from follow-on schedule check
